Workbook

Sheet FBDI Mapping
A1: FBDI Template | B1: FBDI Tab | C1: Applaud Table | D1: Prefix | E1: Status | F1: Module | G1: In Base System?
A2: DosSupplyOrderImportTemplate | B2: Additional Transfer Order Costs | C2: T_ADDITIONALTRANSFERORDERCOST | D2: TL2 | E2: MAPPED | F2: Supply Chain & Manufacturing | G2: =IF(C2="","",_xlfn.LET(_xlpm.v,_xlfn.XLOOKUP(C2,'Applaud Tables Reference'!$A:$A,'Applaud Tables Reference'!$G:$G,"__NF__",0),IF(_xlpm.v="__NF__","Needs to be created in base system",IF(_xlpm.v=0,"",_xlpm.v)))) -> Needs to be created in base system
A3: PayablesStandardInvoiceImportTemplate | B3: AP_INVOICES_INTERFACE | C3: T_AP_INVOICE_INT | D3: TA1 | E3: MAPPED | F3: Financials | G3: =IF(C3="","",_xlfn.LET(_xlpm.v,_xlfn.XLOOKUP(C3,'Applaud Tables Reference'!$A:$A,'Applaud Tables Reference'!$G:$G,"__NF__",0),IF(_xlpm.v="__NF__","Needs to be created in base system",IF(_xlpm.v=0,"",_xlpm.v))))
A4: PayablesStandardInvoiceImportTemplate | B4: AP_INVOICE_LINES_INTERFACE | C4: T_AP_INVOICE_LINES | D4: T99 | E4: MAPPED | F4: Financials | G4: =IF(C4="","",_xlfn.LET(_xlpm.v,_xlfn.XLOOKUP(C4,'Applaud Tables Reference'!$A:$A,'Applaud Tables Reference'!$G:$G,"__NF__",0),IF(_xlpm.v="__NF__","Needs to be created in base system",IF(_xlpm.v=0,"",_xlpm.v))))
A5: ImportAwards | B5: Award Budget Periods | C5: T_AWARD_BUDGET_PERIODS | D5: TF2 | E5: MAPPED | F5: Project Management | G5: =IF(C5="","",_xlfn.LET(_xlpm.v,_xlfn.XLOOKUP(C5,'Applaud Tables Reference'!$A:$A,'Applaud Tables Reference'!$G:$G,"__NF__",0),IF(_xlpm.v="__NF__","Needs to be created in base system",IF(_xlpm.v=0,"",_xlpm.v))))
A6: ImportAwards | B6: Award Certifications | C6: T_AWARD_CERTIFICATIONS | D6: TE7 | E6: MAPPED | F6: Project Management | G6: =IF(C6="","",_xlfn.LET(_xlpm.v,_xlfn.XLOOKUP(C6,'Applaud Tables Reference'!$A:$A,'Applaud Tables Reference'!$G:$G,"__NF__",0),IF(_xlpm.v="__NF__","Needs to be created in base system",IF(_xlpm.v=0,"",_xlpm.v))))
A7: ImportAwards | B7: Award Assistance Listing Number | C7: T_AWARD_FED_DOM_ASSIST_PRG | D7: TE9 | E7: MAPPED | F7: Project Management | G7: =IF(C7="","",_xlfn.LET(_xlpm.v,_xlfn.XLOOKUP(C7,'Applaud Tables Reference'!$A:$A,'Applaud Tables Reference'!$G:$G,"__NF__",0),IF(_xlpm.v="__NF__","Needs to be created in base system",IF(_xlpm.v=0,"",_xlpm.v))))
A8: ImportAwards | B8: Award Funding | C8: T_AWARD_FUNDING | D8: TF5 | E8: MAPPED | F8: Project Management | G8: =IF(C8="","",_xlfn.LET(_xlpm.v,_xlfn.XLOOKUP(C8,'Applaud Tables Reference'!$A:$A,'Applaud Tables Reference'!$G:$G,"__NF__",0),IF(_xlpm.v="__NF__","Needs to be created in base system",IF(_xlpm.v=0,"",_xlpm.v))))
A9: ImportAwards | B9: Award Funding Allocations | C9: T_AWARD_FUNDING_ALLOCATIONS | D9: TF6 | E9: MAPPED | F9: Project Management | G9: =IF(C9="","",_xlfn.LET(_xlpm.v,_xlfn.XLOOKUP(C9,'Applaud Tables Reference'!$A:$A,'Applaud Tables Reference'!$G:$G,"__NF__",0),IF(_xlpm.v="__NF__","Needs to be created in base system",IF(_xlpm.v=0,"",_xlpm.v))))
A10: ImportAwards | B10: Award Funding Sources | C10: T_AWARD_FUNDING_SOURCE | D10: TE2 | E10: MAPPED | F10: Project Management | G10: =IF(C10="","",_xlfn.LET(_xlpm.v,_xlfn.XLOOKUP(C10,'Applaud Tables Reference'!$A:$A,'Applaud Tables Reference'!$G:$G,"__NF__",0),IF(_xlpm.v="__NF__","Needs to be created in base system",IF(_xlpm.v=0,"",_xlpm.v))))
A11: ImportAwards | B11: Award Keywords | C11: T_AWARD_KEYWORDS | D11: TE5 | E11: MAPPED | F11: Project Management | G11: =IF(C11="","",_xlfn.LET(_xlpm.v,_xlfn.XLOOKUP(C11,'Applaud Tables Reference'!$A:$A,'Applaud Tables Reference'!$G:$G,"__NF__",0),IF(_xlpm.v="__NF__","Needs to be created in base system",IF(_xlpm.v=0,"",_xlpm.v))))
A12: ImportAwards | B12: Award Organization Credits | C12: T_AWARD_ORGANIZATION_CREDITS | D12: TF3 | E12: MAPPED | F12: Project Management | G12: =IF(C12="","",_xlfn.LET(_xlpm.v,_xlfn.XLOOKUP(C12,'Applaud Tables Reference'!$A:$A,'Applaud Tables Reference'!$G:$G,"__NF__",0),IF(_xlpm.v="__NF__","Needs to be created in base system",IF(_xlpm.v=0,"",_xlpm.v))))
A13: ImportAwards | B13: Award Personnel | C13: T_AWARD_PERSONNEL | D13: TF4 | E13: MAPPED | F13: Project Management | G13: =IF(C13="","",_xlfn.LET(_xlpm.v,_xlfn.XLOOKUP(C13,'Applaud Tables Reference'!$A:$A,'Applaud Tables Reference'!$G:$G,"__NF__",0),IF(_xlpm.v="__NF__","Needs to be created in base system",IF(_xlpm.v=0,"",_xlpm.v))))
... A88: CreateBillingEventsTemplate | B88: Project Billing Events | C88: T_PJB_BILLING_EVENTS_INT | D88: T38 | E88: MAPPED | F88: Project Management | G88: =IF(C88="","",_xlfn.LET(_xlpm.v,_xlfn.XLOOKUP(C88,'Applaud Tables Reference'!$A:$A,'Applaud Tables Reference'!$G:$G,"__NF__",0),IF(_xlpm.v="__NF__","Needs to be created in base system",IF(_xlpm.v=0,"",_xlpm.v))))
A89: ProjectUnprocessedExpenseReportExpenditureItemImportTemplate | B89: PJC_TXN_XFACE_STAGE_ALL | C89: T_PJC_TXN_XFACE_STAGE_ALL | D89: T39 | E89: MAPPED | F89: Project Management | G89: Multiple mapping is possible. Each Oracle FBDI is different. Would need ALL data elements on Applaud table. Would need unique IFs and EFs for each Oracle FBDI.
A90: ProjectUnprocessedInventoryExpenditureItemImportTemplate | B90: PJC_TXN_XFACE_STAGE_ALL | C90: T_PJC_TXN_XFACE_STAGE_ALL | D90: T39 | E90: MAPPED | F90: Project Management | G90: Multiple mapping is possible. Each Oracle FBDI is different. Would need ALL data elements on Applaud table. Would need unique IFs and EFs for each Oracle FBDI.
A91: ProjectUnprocessedLaborExpenditureItemImportTemplate | B91: PJC_TXN_XFACE_STAGE_ALL | C91: T_PJC_TXN_XFACE_STAGE_ALL | D91: T39 | E91: MAPPED | F91: Project Management | G91: Multiple mapping is possible. Each Oracle FBDI is different. Would need ALL data elements on Applaud table. Would need unique IFs and EFs for each Oracle FBDI.
A92: ProjectUnprocessedMiscellaneousExpenditureItemImportTemplate | B92: PJC_TXN_XFACE_STAGE_ALL | C92: T_PJC_TXN_XFACE_STAGE_ALL | D92: T39 | E92: MAPPED | F92: Project Management | G92: Multiple mapping is possible. Each Oracle FBDI is different. Would need ALL data elements on Applaud table. Would need unique IFs and EFs for each Oracle FBDI.
A93: ProjectUnprocessedNonlaborExpenditureItemImportTemplate | B93: PJC_TXN_XFACE_STAGE_ALL | C93: T_PJC_TXN_XFACE_STAGE_ALL | D93: T39 | E93: MAPPED | F93: Project Management | G93: Multiple mapping is possible. Each Oracle FBDI is different. Would need ALL data elements on Applaud table. Would need unique IFs and EFs for each Oracle FBDI.
A94: ProjectUnprocessedSupplierInvoiceExpenditureItemImportTemplate | B94: PJC_TXN_XFACE_STAGE_ALL | C94: T_PJC_TXN_XFACE_STAGE_ALL | D94: T39 | E94: MAPPED | F94: Project Management | G94: Multiple mapping is possible. Each Oracle FBDI is different. Would need ALL data elements on Applaud table. Would need unique IFs and EFs for each Oracle FBDI.
A95: ProjectTasksImportTemplate | B95: PJF_PROJ_ELEMENTS_XFACE | C95: T_PJF_PROJ_ELEMENTS_XFACE | D95: T53 | E95: MAPPED | F95: Project Management | G95: =IF(C95="","",_xlfn.LET(_xlpm.v,_xlfn.XLOOKUP(C95,'Applaud Tables Reference'!$A:$A,'Applaud Tables Reference'!$G:$G,"__NF__",0),IF(_xlpm.v="__NF__","Needs to be created in base system",IF(_xlpm.v=0,"",_xlpm.v))))
A96: ProjectBudgetsImportTemplate | B96: PJO_BUDGETS_XFACE | C96: T_PJO_BUDGETS_XFACE | D96: T54 | E96: MAPPED | F96: Project Management | G96: =IF(C96="","",_xlfn.LET(_xlpm.v,_xlfn.XLOOKUP(C96,'Applaud Tables Reference'!$A:$A,'Applaud Tables Reference'!$G:$G,"__NF__",0),IF(_xlpm.v="__NF__","Needs to be created in base system",IF(_xlpm.v=0,"",_xlpm.v))))
A97: POPurchaseOrderImportTemplate | B97: PO_DISTRIBUTIONS_INTERFACE | C97: T_PO_DISTRIBUTIONS_INTERFACE | D97: T75 | E97: MAPPED | F97: Procurement | G97: =IF(C97="","",_xlfn.LET(_xlpm.v,_xlfn.XLOOKUP(C97,'Applaud Tables Reference'!$A:$A,'Applaud Tables Reference'!$G:$G,"__NF__",0),IF(_xlpm.v="__NF__","Needs to be created in base system",IF(_xlpm.v=0,"",_xlpm.v))))
A98: POPurchaseOrderImportTemplate | B98: PO_HEADERS_INTERFACE | C98: T_PO_HEADERS_INTERFACE | D98: T77 | E98: MAPPED | F98: Procurement | G98: =IF(C98="","",_xlfn.LET(_xlpm.v,_xlfn.XLOOKUP(C98,'Applaud Tables Reference'!$A:$A,'Applaud Tables Reference'!$G:$G,"__NF__",0),IF(_xlpm.v="__NF__","Needs to be created in base system",IF(_xlpm.v=0,"",_xlpm.v))))
A99: POPurchaseOrderImportTemplate | B99: PO_LINE_LOCATIONS_INTERFACE | C99: T_PO_LINE_LOCATIONS_INTERFACE | D99: T78 | E99: MAPPED | F99: Procurement | G99: =IF(C99="","",_xlfn.LET(_xlpm.v,_xlfn.XLOOKUP(C99,'Applaud Tables Reference'!$A:$A,'Applaud Tables Reference'!$G:$G,"__NF__",0),IF(_xlpm.v="__NF__","Needs to be created in base system",IF(_xlpm.v=0,"",_xlpm.v))))
A100: POPurchaseOrderImportTemplate | B100: PO_LINES_INTERFACE | C100: T_PO_LINES_INTERFACE | D100: T79 | E100: MAPPED | F100: Procurement | G100: =IF(C100="","",_xlfn.LET(_xlpm.v,_xlfn.XLOOKUP(C100,'Applaud Tables Reference'!$A:$A,'Applaud Tables Reference'!$G:$G,"__NF__",0),IF(_xlpm.v="__NF__","Needs to be created in base system",IF(_xlpm.v=0,"",_xlpm.v))))
A101: SupplierSiteAssignmentImportTemplate | B101: POZ_SITE_ASSIGNMENTS_INT | C101: T_POZ_SITE_ASSIGNMENTS_INT | D101: T10 | E101: MAPPED | F101: Procurement | G101: =IF(C101="","",_xlfn.LET(_xlpm.v,_xlfn.XLOOKUP(C101,'Applaud Tables Reference'!$A:$A,'Applaud Tables Reference'!$G:$G,"__NF__",0),IF(_xlpm.v="__NF__","Needs to be created in base system",IF(_xlpm.v=0,"",_xlpm.v))))
A102: SupplierAddressImportTemplate | B102: POZ_SUPPLIER_ADDRESSES_INT | C102: T_POZ_SUP_ADDRESSES_INT | D102: T08 | E102: MAPPED | F102: Procurement | G102: =IF(C102="","",_xlfn.LET(_xlpm.v,_xlfn.XLOOKUP(C102,'Applaud Tables Reference'!$A:$A,'Applaud Tables Reference'!$G:$G,"__NF__",0),IF(_xlpm.v="__NF__","Needs to be created in base system",IF(_xlpm.v=0,"",_xlpm.v))))
A103: SupplierBusinessClassificationImportTemplate | B103: POZ_SUP_BUS_CLASS_INT | C103: T_POZ_SUP_BUS_CLASS_INT | D103: T13 | E103: MAPPED | F103: Procurement | G103: =IF(C103="","",_xlfn.LET(_xlpm.v,_xlfn.XLOOKUP(C103,'Applaud Tables Reference'!$A:$A,'Applaud Tables Reference'!$G:$G,"__NF__",0),IF(_xlpm.v="__NF__","Needs to be created in base system",IF(_xlpm.v=0,"",_xlpm.v))))
A104: SupplierContactImportTemplate | B104: POZ_SUPP_CONTACT_ADDRESSES_INT | C104: T_POZ_SUP_CONTACT_ADDRESS_INT | D104: T12 | E104: MAPPED | F104: Procurement | G104: =IF(C104="","",_xlfn.LET(_xlpm.v,_xlfn.XLOOKUP(C104,'Applaud Tables Reference'!$A:$A,'Applaud Tables Reference'!$G:$G,"__NF__",0),IF(_xlpm.v="__NF__","Needs to be created in base system",IF(_xlpm.v=0,"",_xlpm.v))))
A105: SupplierContactImportTemplate | B105: POZ_SUP_CONTACTS | C105: T_POZ_SUP_CONTACTS_INT | D105: T11 | E105: MAPPED | F105: Procurement | G105: =IF(C105="","",_xlfn.LET(_xlpm.v,_xlfn.XLOOKUP(C105,'Applaud Tables Reference'!$A:$A,'Applaud Tables Reference'!$G:$G,"__NF__",0),IF(_xlpm.v="__NF__","Needs to be created in base system",IF(_xlpm.v=0,"",_xlpm.v))))
A106: SupplierSiteImportTemplate | B106: Third_Party_Pay_Relationships | C106: T_POZ_SUP_THIRDPARTY_INT | D106: TE1 | E106: MAPPED | F106: Procurement | G106: =IF(C106="","",_xlfn.LET(_xlpm.v,_xlfn.XLOOKUP(C106,'Applaud Tables Reference'!$A:$A,'Applaud Tables Reference'!$G:$G,"__NF__",0),IF(_xlpm.v="__NF__","Needs to be created in base system",IF(_xlpm.v=0,"",_xlpm.v))))
... A155: PerformShippingTransactionImportTemplate | B155: WSH_SHIPMENT_LINE_INTERFACE | C155: T_WSH_SHIPMENT_LINE_INTERFACE | D155: TK5 | E155: MAPPED | F155: Supply Chain & Manufacturing | G155: =IF(C155="","",_xlfn.LET(_xlpm.v,_xlfn.XLOOKUP(C155,'Applaud Tables Reference'!$A:$A,'Applaud Tables Reference'!$G:$G,"__NF__",0),IF(_xlpm.v="__NF__","Needs to be created in base system",IF(_xlpm.v=0,"",_xlpm.v)))) -> Needs to be created in base system
A156: MaintenanceWorkOrderTemplate | B156: Import Batches | E156: UNMAPPED | F156: Supply Chain & Manufacturing | G156: =IF(C156="","",_xlfn.LET(_xlpm.v,_xlfn.XLOOKUP(C156,'Applaud Tables Reference'!$A:$A,'Applaud Tables Reference'!$G:$G,"__NF__",0),IF(_xlpm.v="__NF__","Needs to be created in base system",IF(_xlpm.v=0,"",_xlpm.v))))
A157: ProcessWorkOrderTemplate | B157: Work Order Batches | E157: UNMAPPED | F157: Supply Chain & Manufacturing | G157: =IF(C157="","",_xlfn.LET(_xlpm.v,_xlfn.XLOOKUP(C157,'Applaud Tables Reference'!$A:$A,'Applaud Tables Reference'!$G:$G,"__NF__",0),IF(_xlpm.v="__NF__","Needs to be created in base system",IF(_xlpm.v=0,"",_xlpm.v))))
A158: MaintenanceWorkOrderTemplate | B158: Work orders | E158: UNMAPPED | F158: Supply Chain & Manufacturing | G158: =IF(C158="","",_xlfn.LET(_xlpm.v,_xlfn.XLOOKUP(C158,'Applaud Tables Reference'!$A:$A,'Applaud Tables Reference'!$G:$G,"__NF__",0),IF(_xlpm.v="__NF__","Needs to be created in base system",IF(_xlpm.v=0,"",_xlpm.v))))
A159: ProcessWorkOrderTemplate | B159: Work Order Header | E159: UNMAPPED | F159: Supply Chain & Manufacturing | G159: =IF(C159="","",_xlfn.LET(_xlpm.v,_xlfn.XLOOKUP(C159,'Applaud Tables Reference'!$A:$A,'Applaud Tables Reference'!$G:$G,"__NF__",0),IF(_xlpm.v="__NF__","Needs to be created in base system",IF(_xlpm.v=0,"",_xlpm.v))))
A160: MaintenanceWorkOrderTemplate | B160: Operation Materials | E160: UNMAPPED | F160: Supply Chain & Manufacturing | G160: =IF(C160="","",_xlfn.LET(_xlpm.v,_xlfn.XLOOKUP(C160,'Applaud Tables Reference'!$A:$A,'Applaud Tables Reference'!$G:$G,"__NF__",0),IF(_xlpm.v="__NF__","Needs to be created in base system",IF(_xlpm.v=0,"",_xlpm.v))))
A161: ProcessWorkOrderTemplate | B161: Work Order Operation Materials | E161: UNMAPPED | F161: Supply Chain & Manufacturing | G161: =IF(C161="","",_xlfn.LET(_xlpm.v,_xlfn.XLOOKUP(C161,'Applaud Tables Reference'!$A:$A,'Applaud Tables Reference'!$G:$G,"__NF__",0),IF(_xlpm.v="__NF__","Needs to be created in base system",IF(_xlpm.v=0,"",_xlpm.v))))
A162: MaintenanceWorkOrderTemplate | B162: Operation resources | E162: UNMAPPED | F162: Supply Chain & Manufacturing | G162: =IF(C162="","",_xlfn.LET(_xlpm.v,_xlfn.XLOOKUP(C162,'Applaud Tables Reference'!$A:$A,'Applaud Tables Reference'!$G:$G,"__NF__",0),IF(_xlpm.v="__NF__","Needs to be created in base system",IF(_xlpm.v=0,"",_xlpm.v))))
...

Sheet Applaud Tables Reference
A1: Applaud Table | B1: Status | C1: Prefix | D1: FBDI Template Mappings
A2: T_AP_INVOICE_INT | B2: =_xlfn.XLOOKUP(A2,'FBDI Mapping'!C:C,'FBDI Mapping'!E:E,"UNMAPPED",0) -> MAPPED | C2: TA1 | D2: {=IFERROR(_xlfn.TEXTJOIN(", ",TRUE,IF('FBDI Mapping'!$C$2:$C$640=A2,'FBDI Mapping'!$A$2:$A$640,"")),"")} -> PayablesStandardInvoiceImportTemplate
A3: T_AP_INVOICE_LINES | B3: =_xlfn.XLOOKUP(A3,'FBDI Mapping'!C:C,'FBDI Mapping'!E:E,"UNMAPPED",0) -> MAPPED | C3: T99 | D3: {=IFERROR(_xlfn.TEXTJOIN(", ",TRUE,IF('FBDI Mapping'!$C$2:$C$640=A3,'FBDI Mapping'!$A$2:$A$640,"")),"")} -> PayablesStandardInvoiceImportTemplate
A4: T_AWARD_BUDGET_PERIODS | B4: =_xlfn.XLOOKUP(A4,'FBDI Mapping'!C:C,'FBDI Mapping'!E:E,"UNMAPPED",0) -> MAPPED | C4: TF2 | D4: {=IFERROR(_xlfn.TEXTJOIN(", ",TRUE,IF('FBDI Mapping'!$C$2:$C$640=A4,'FBDI Mapping'!$A$2:$A$640,"")),"")} -> ImportAwards
A5: T_AWARD_CERTIFICATIONS | B5: =_xlfn.XLOOKUP(A5,'FBDI Mapping'!C:C,'FBDI Mapping'!E:E,"UNMAPPED",0) -> MAPPED | C5: TE7 | D5: {=IFERROR(_xlfn.TEXTJOIN(", ",TRUE,IF('FBDI Mapping'!$C$2:$C$640=A5,'FBDI Mapping'!$A$2:$A$640,"")),"")} -> ImportAwards
A6: T_AWARD_FED_DOM_ASSIST_PRG | B6: =_xlfn.XLOOKUP(A6,'FBDI Mapping'!C:C,'FBDI Mapping'!E:E,"UNMAPPED",0) -> MAPPED | C6: TE9 | D6: {=IFERROR(_xlfn.TEXTJOIN(", ",TRUE,IF('FBDI Mapping'!$C$2:$C$640=A6,'FBDI Mapping'!$A$2:$A$640,"")),"")} -> ImportAwards
A7: T_AWARD_FUNDING | B7: =_xlfn.XLOOKUP(A7,'FBDI Mapping'!C:C,'FBDI Mapping'!E:E,"UNMAPPED",0) -> MAPPED | C7: TF5 | D7: {=IFERROR(_xlfn.TEXTJOIN(", ",TRUE,IF('FBDI Mapping'!$C$2:$C$640=A7,'FBDI Mapping'!$A$2:$A$640,"")),"")} -> ImportAwards
A8: T_AWARD_FUNDING_ALLOCATIONS | B8: =_xlfn.XLOOKUP(A8,'FBDI Mapping'!C:C,'FBDI Mapping'!E:E,"UNMAPPED",0) -> MAPPED | C8: TF6 | D8: {=IFERROR(_xlfn.TEXTJOIN(", ",TRUE,IF('FBDI Mapping'!$C$2:$C$640=A8,'FBDI Mapping'!$A$2:$A$640,"")),"")} -> ImportAwards
A9: T_AWARD_FUNDING_SOURCE | B9: =_xlfn.XLOOKUP(A9,'FBDI Mapping'!C:C,'FBDI Mapping'!E:E,"UNMAPPED",0) -> MAPPED | C9: TE2 | D9: {=IFERROR(_xlfn.TEXTJOIN(", ",TRUE,IF('FBDI Mapping'!$C$2:$C$640=A9,'FBDI Mapping'!$A$2:$A$640,"")),"")} -> ImportAwards
A10: T_AWARD_KEYWORDS | B10: =_xlfn.XLOOKUP(A10,'FBDI Mapping'!C:C,'FBDI Mapping'!E:E,"UNMAPPED",0) -> MAPPED | C10: TE5 | D10: {=IFERROR(_xlfn.TEXTJOIN(", ",TRUE,IF('FBDI Mapping'!$C$2:$C$640=A10,'FBDI Mapping'!$A$2:$A$640,"")),"")} -> ImportAwards
A11: T_AWARD_ORGANIZATION_CREDITS | B11: =_xlfn.XLOOKUP(A11,'FBDI Mapping'!C:C,'FBDI Mapping'!E:E,"UNMAPPED",0) -> MAPPED | C11: TF3 | D11: {=IFERROR(_xlfn.TEXTJOIN(", ",TRUE,IF('FBDI Mapping'!$C$2:$C$640=A11,'FBDI Mapping'!$A$2:$A$640,"")),"")} -> ImportAwards
A12: T_AWARD_PERSONNEL | B12: =_xlfn.XLOOKUP(A12,'FBDI Mapping'!C:C,'FBDI Mapping'!E:E,"UNMAPPED",0) -> MAPPED | C12: TF4 | D12: {=IFERROR(_xlfn.TEXTJOIN(", ",TRUE,IF('FBDI Mapping'!$C$2:$C$640=A12,'FBDI Mapping'!$A$2:$A$640,"")),"")} -> ImportAwards
A13: T_AWARD_PRJ_TASK_BURDEN_SCHED | B13: =_xlfn.XLOOKUP(A13,'FBDI Mapping'!C:C,'FBDI Mapping'!E:E,"UNMAPPED",0) -> MAPPED | C13: TF7 | D13: {=IFERROR(_xlfn.TEXTJOIN(", ",TRUE,IF('FBDI Mapping'!$C$2:$C$640=A13,'FBDI Mapping'!$A$2:$A$640,"")),"")} -> ImportAwards
... A158: T_WSH_TRANSIT_TIMES | B158: =_xlfn.XLOOKUP(A158,'FBDI Mapping'!C:C,'FBDI Mapping'!E:E,"UNMAPPED",0) -> UNMAPPED | C158: T46 | D158: {=IFERROR(_xlfn.TEXTJOIN(", ",TRUE,IF('FBDI Mapping'!$C$2:$C$640=A158,'FBDI Mapping'!$A$2:$A$640,"")),"")}
